[2023-04-01T13:29:16.235+0000] {taskinstance.py:1083} INFO - Dependencies all met for <TaskInstance: twitter_status_with_image_update.tweet_image manual__2023-04-01T13:19:01.944523+00:00 [queued]>
[2023-04-01T13:29:16.243+0000] {taskinstance.py:1083} INFO - Dependencies all met for <TaskInstance: twitter_status_with_image_update.tweet_image manual__2023-04-01T13:19:01.944523+00:00 [queued]>
[2023-04-01T13:29:16.245+0000] {taskinstance.py:1279} INFO - 
--------------------------------------------------------------------------------
[2023-04-01T13:29:16.246+0000] {taskinstance.py:1280} INFO - Starting attempt 3 of 3
[2023-04-01T13:29:16.247+0000] {taskinstance.py:1281} INFO - 
--------------------------------------------------------------------------------
[2023-04-01T13:29:16.260+0000] {taskinstance.py:1300} INFO - Executing <Task(_PythonDecoratedOperator): tweet_image> on 2023-04-01 13:19:01.944523+00:00
[2023-04-01T13:29:16.270+0000] {standard_task_runner.py:55} INFO - Started process 13022 to run task
[2023-04-01T13:29:16.277+0000] {standard_task_runner.py:82} INFO - Running: ['***', 'tasks', 'run', 'twitter_status_with_image_update', 'tweet_image', 'manual__2023-04-01T13:19:01.944523+00:00', '--job-id', '133', '--raw', '--subdir', 'DAGS_FOLDER/twitterImageWithTextUpdatePipeline.py', '--cfg-path', '/tmp/tmpyw3vccca']
[2023-04-01T13:29:16.281+0000] {standard_task_runner.py:83} INFO - Job 133: Subtask tweet_image
[2023-04-01T13:29:16.373+0000] {task_command.py:388} INFO - Running <TaskInstance: twitter_status_with_image_update.tweet_image manual__2023-04-01T13:19:01.944523+00:00 [running]> on host 21dcead862af
[2023-04-01T13:29:16.438+0000] {taskinstance.py:1509} INFO - Exporting the following env vars:
AIRFLOW_CTX_DAG_OWNER=***
AIRFLOW_CTX_DAG_ID=twitter_status_with_image_update
AIRFLOW_CTX_TASK_ID=tweet_image
AIRFLOW_CTX_EXECUTION_DATE=2023-04-01T13:19:01.944523+00:00
AIRFLOW_CTX_TRY_NUMBER=3
AIRFLOW_CTX_DAG_RUN_ID=manual__2023-04-01T13:19:01.944523+00:00
[2023-04-01T13:29:16.442+0000] {taskinstance.py:1768} ERROR - Task failed with exception
Traceback (most recent call last):
  File "/home/airflow/.local/lib/python3.7/site-packages/airflow/decorators/base.py", line 217, in execute
    return_value = super().execute(context)
  File "/home/airflow/.local/lib/python3.7/site-packages/airflow/operators/python.py", line 175, in execute
    return_value = self.execute_callable()
  File "/home/airflow/.local/lib/python3.7/site-packages/airflow/operators/python.py", line 192, in execute_callable
    return self.python_callable(*self.op_args, **self.op_kwargs)
  File "/opt/airflow/dags/twitterImageWithTextUpdatePipeline.py", line 52, in tweet_image
    image_name = image_details["image_name"]
KeyError: 'image_name'
[2023-04-01T13:29:16.452+0000] {taskinstance.py:1323} INFO - Marking task as FAILED. dag_id=twitter_status_with_image_update, task_id=tweet_image, execution_date=20230401T131901, start_date=20230401T132916, end_date=20230401T132916
[2023-04-01T13:29:16.491+0000] {standard_task_runner.py:105} ERROR - Failed to execute job 133 for task tweet_image ('image_name'; 13022)
[2023-04-01T13:29:16.539+0000] {local_task_job.py:208} INFO - Task exited with return code 1
[2023-04-01T13:29:16.557+0000] {taskinstance.py:2578} INFO - 0 downstream tasks scheduled from follow-on schedule check
