[2023-04-01T15:52:54.197+0000] {taskinstance.py:1083} INFO - Dependencies all met for <TaskInstance: pythonoperator_demo.python_task manual__2023-04-01T15:52:52.160854+00:00 [queued]>
[2023-04-01T15:52:54.205+0000] {taskinstance.py:1083} INFO - Dependencies all met for <TaskInstance: pythonoperator_demo.python_task manual__2023-04-01T15:52:52.160854+00:00 [queued]>
[2023-04-01T15:52:54.206+0000] {taskinstance.py:1279} INFO - 
--------------------------------------------------------------------------------
[2023-04-01T15:52:54.207+0000] {taskinstance.py:1280} INFO - Starting attempt 1 of 1
[2023-04-01T15:52:54.208+0000] {taskinstance.py:1281} INFO - 
--------------------------------------------------------------------------------
[2023-04-01T15:52:54.218+0000] {taskinstance.py:1300} INFO - Executing <Task(PythonOperator): python_task> on 2023-04-01 15:52:52.160854+00:00
[2023-04-01T15:52:54.223+0000] {standard_task_runner.py:55} INFO - Started process 518 to run task
[2023-04-01T15:52:54.227+0000] {standard_task_runner.py:82} INFO - Running: ['***', 'tasks', 'run', 'pythonoperator_demo', 'python_task', 'manual__2023-04-01T15:52:52.160854+00:00', '--job-id', '139', '--raw', '--subdir', 'DAGS_FOLDER/pythonoperator_demo.py', '--cfg-path', '/tmp/tmpg4rufwur']
[2023-04-01T15:52:54.228+0000] {standard_task_runner.py:83} INFO - Job 139: Subtask python_task
[2023-04-01T15:52:54.299+0000] {task_command.py:388} INFO - Running <TaskInstance: pythonoperator_demo.python_task manual__2023-04-01T15:52:52.160854+00:00 [running]> on host 16ecf75c2681
[2023-04-01T15:52:54.358+0000] {taskinstance.py:1509} INFO - Exporting the following env vars:
AIRFLOW_CTX_DAG_OWNER=***
AIRFLOW_CTX_DAG_ID=pythonoperator_demo
AIRFLOW_CTX_TASK_ID=python_task
AIRFLOW_CTX_EXECUTION_DATE=2023-04-01T15:52:52.160854+00:00
AIRFLOW_CTX_TRY_NUMBER=1
AIRFLOW_CTX_DAG_RUN_ID=manual__2023-04-01T15:52:52.160854+00:00
[2023-04-01T15:52:54.360+0000] {taskinstance.py:1768} ERROR - Task failed with exception
Traceback (most recent call last):
  File "/home/airflow/.local/lib/python3.7/site-packages/airflow/operators/python.py", line 175, in execute
    return_value = self.execute_callable()
  File "/home/airflow/.local/lib/python3.7/site-packages/airflow/operators/python.py", line 192, in execute_callable
    return self.python_callable(*self.op_args, **self.op_kwargs)
  File "/opt/airflow/dags/pythonoperator_demo.py", line 15, in my_func
    files = {'media': open('BoolDataTypeKeyword_ManimCE_v0.17.2.png', 'rb')}
FileNotFoundError: [Errno 2] No such file or directory: 'BoolDataTypeKeyword_ManimCE_v0.17.2.png'
[2023-04-01T15:52:54.370+0000] {taskinstance.py:1323} INFO - Marking task as FAILED. dag_id=pythonoperator_demo, task_id=python_task, execution_date=20230401T155252, start_date=20230401T155254, end_date=20230401T155254
[2023-04-01T15:52:54.382+0000] {standard_task_runner.py:105} ERROR - Failed to execute job 139 for task python_task ([Errno 2] No such file or directory: 'BoolDataTypeKeyword_ManimCE_v0.17.2.png'; 518)
[2023-04-01T15:52:54.400+0000] {local_task_job.py:208} INFO - Task exited with return code 1
[2023-04-01T15:52:54.412+0000] {taskinstance.py:2578} INFO - 0 downstream tasks scheduled from follow-on schedule check
