[2023-04-01T09:32:27.932+0000] {taskinstance.py:1083} INFO - Dependencies all met for <TaskInstance: bq_test_pipeline.updateStatus manual__2023-04-01T09:32:25.285454+00:00 [queued]>
[2023-04-01T09:32:27.939+0000] {taskinstance.py:1083} INFO - Dependencies all met for <TaskInstance: bq_test_pipeline.updateStatus manual__2023-04-01T09:32:25.285454+00:00 [queued]>
[2023-04-01T09:32:27.940+0000] {taskinstance.py:1279} INFO - 
--------------------------------------------------------------------------------
[2023-04-01T09:32:27.941+0000] {taskinstance.py:1280} INFO - Starting attempt 1 of 3
[2023-04-01T09:32:27.942+0000] {taskinstance.py:1281} INFO - 
--------------------------------------------------------------------------------
[2023-04-01T09:32:27.951+0000] {taskinstance.py:1300} INFO - Executing <Task(_PythonDecoratedOperator): updateStatus> on 2023-04-01 09:32:25.285454+00:00
[2023-04-01T09:32:27.956+0000] {standard_task_runner.py:55} INFO - Started process 138 to run task
[2023-04-01T09:32:27.958+0000] {standard_task_runner.py:82} INFO - Running: ['***', 'tasks', 'run', 'bq_test_pipeline', 'updateStatus', 'manual__2023-04-01T09:32:25.285454+00:00', '--job-id', '75', '--raw', '--subdir', 'DAGS_FOLDER/bq_pipeline.py', '--cfg-path', '/tmp/tmpyxtp9ufb']
[2023-04-01T09:32:27.959+0000] {standard_task_runner.py:83} INFO - Job 75: Subtask updateStatus
[2023-04-01T09:32:28.006+0000] {task_command.py:388} INFO - Running <TaskInstance: bq_test_pipeline.updateStatus manual__2023-04-01T09:32:25.285454+00:00 [running]> on host dbc731dd7c2b
[2023-04-01T09:32:28.053+0000] {taskinstance.py:1509} INFO - Exporting the following env vars:
AIRFLOW_CTX_DAG_OWNER=***
AIRFLOW_CTX_DAG_ID=bq_test_pipeline
AIRFLOW_CTX_TASK_ID=updateStatus
AIRFLOW_CTX_EXECUTION_DATE=2023-04-01T09:32:25.285454+00:00
AIRFLOW_CTX_TRY_NUMBER=1
AIRFLOW_CTX_DAG_RUN_ID=manual__2023-04-01T09:32:25.285454+00:00
[2023-04-01T09:32:31.975+0000] {_metadata.py:104} WARNING - Compute Engine Metadata server unavailable on attempt 1 of 3. Reason: timed out
[2023-04-01T09:32:31.982+0000] {_metadata.py:104} WARNING - Compute Engine Metadata server unavailable on attempt 2 of 3. Reason: [Errno 111] Connection refused
[2023-04-01T09:32:31.984+0000] {_metadata.py:104} WARNING - Compute Engine Metadata server unavailable on attempt 3 of 3. Reason: [Errno 111] Connection refused
[2023-04-01T09:32:31.985+0000] {_default.py:302} WARNING - Authentication failed using Compute Engine authentication due to unavailable metadata server.
[2023-04-01T09:32:31.987+0000] {taskinstance.py:1768} ERROR - Task failed with exception
Traceback (most recent call last):
  File "/home/airflow/.local/lib/python3.7/site-packages/airflow/decorators/base.py", line 217, in execute
    return_value = super().execute(context)
  File "/home/airflow/.local/lib/python3.7/site-packages/airflow/operators/python.py", line 175, in execute
    return_value = self.execute_callable()
  File "/home/airflow/.local/lib/python3.7/site-packages/airflow/operators/python.py", line 192, in execute_callable
    return self.python_callable(*self.op_args, **self.op_kwargs)
  File "/opt/airflow/dags/bq_pipeline.py", line 29, in updateStatus
    client = bigquery.Client(project="airflow-dev-382217")
  File "/home/airflow/.local/lib/python3.7/site-packages/google/cloud/bigquery/client.py", line 235, in __init__
    _http=_http,
  File "/home/airflow/.local/lib/python3.7/site-packages/google/cloud/client/__init__.py", line 322, in __init__
    self, credentials=credentials, client_options=client_options, _http=_http
  File "/home/airflow/.local/lib/python3.7/site-packages/google/cloud/client/__init__.py", line 178, in __init__
    credentials, _ = google.auth.default(scopes=scopes)
  File "/home/airflow/.local/lib/python3.7/site-packages/google/auth/_default.py", line 653, in default
    raise exceptions.DefaultCredentialsError(_HELP_MESSAGE)
google.auth.exceptions.DefaultCredentialsError: Could not automatically determine credentials. Please set GOOGLE_APPLICATION_CREDENTIALS or explicitly create credentials and re-run the application. For more information, please see https://cloud.google.com/docs/authentication/getting-started
[2023-04-01T09:32:32.002+0000] {taskinstance.py:1323} INFO - Marking task as UP_FOR_RETRY. dag_id=bq_test_pipeline, task_id=updateStatus, execution_date=20230401T093225, start_date=20230401T093227, end_date=20230401T093232
[2023-04-01T09:32:32.013+0000] {standard_task_runner.py:105} ERROR - Failed to execute job 75 for task updateStatus (Could not automatically determine credentials. Please set GOOGLE_APPLICATION_CREDENTIALS or explicitly create credentials and re-run the application. For more information, please see https://cloud.google.com/docs/authentication/getting-started; 138)
[2023-04-01T09:32:32.057+0000] {local_task_job.py:208} INFO - Task exited with return code 1
[2023-04-01T09:32:32.071+0000] {taskinstance.py:2578} INFO - 0 downstream tasks scheduled from follow-on schedule check
